Workbook

Sheet Demanda Bruta
A1: processo | B1: modalidade | C1: nivel | D1: inicio | E1: termino | F1: cpf_proponente | G1: proponente | H1: link_cvlattes_proponente | I1: beneficiario | J1: orientador_proponente | K1: membros_equipe | L1: proposta | M1: titulo_projeto | N1: programa | O1: ca | P1: grande_area_conhecimento | Q1: area_conhecimento | R1: instituicao_origem | S1: instituicao_origem_sigla | T1: instituicao_origem_uf | U1: instituicao_origem_regiao | V1: instituicao_origem_pais | W1: instituicao_destino | X1: instituicao_destino_sigla | Y1: instituicao_destino_uf | Z1: instituicao_destino_regiao | AA1: instituicao_destino_pais | AB1: diretoria | AC1: unidade | AD1: data_envio | AE1: hora_envio | AF1: data_carga | AG1: hora_carga | AH1: quantidade_bolsa | AI1: valor_bolsa | AJ1: valor_custeio | AK1: valor_capital | AL1: valor_total | AM1: instituicao_vinculo | AN1: sigla_inst_vinculo | AO1: uf_inst_vinculo | AP1: regiao_inst_vinculo | AQ1: pais_inst_vinculo | AR1: id_lattes | AS1: data_importacao | AT1: sigla_chamada | AU1: nome_chamada | AV1: nome_chamada_arquivo | AW1: numero_chamada | AX1: linha_chamada | AY1: inicio_submissao | AZ1: termino_submissao | BA1: email | BB1: Número do Processo | BC1: Nome do Pesquisador | BD1: Instituição de Execução do Processo | BE1: Sigla da Instituição | BF1: Pré-Selecionado? | BG1: Instituição Permitida (MCTI)? | BH1: Ano do Primeiro Doutorado | BI1: Enviou Carta de Anuência? | BJ1: Faixa/Linha da Proposta | BK1: Faixa Majoritária da Instituição | BL1: Faixa Majoritária (=Faixa=ESQUERDA(Majoritária;7)) | BM1: Vínculo com Inst. Executora? | BN1: Vínculo Executora é Celetista/Estatutário? | BO1: Vínculos Ativos (Lattes) | BP1: Sendo Avaliada?
A2: 402356/2026-8 | B2: APQ | D2: 46204 | E2: 47664 | F2: 46624198087 | G2: Alexandre Bragio Bonaldo | H2: http://lattes.cnpq.br/8721994758453503 | I2: Alexandre Bragio Bonaldo | K2: Alexandre Bragio Bonaldo, Antonio Domingos Brescovit, Facundo Martín Labarque, Leonardo Sousa Carvalho, Ivan Luiz Fiorini de Magalhães, Martin Ramirez, Paulo Roberto Pantoja Gomes, Marcos Quintino Drago Bisneto, Cláudio | L2: 5116854 | M2: Sistemática e taxonomia integrativa de aranhas-soldado e aranhas-raio (Araneae: Corinnidae Karsh, 1880; Theridiosomatidae Simon, 1881) | N2: PROGRAMA BASICO DE ZOOLOGIA E RECURSOS PESQUEIROS DE AGUAS INTERIORES | O2: ZO | P2: Ciências Biológicas | Q2: Taxonomia dos Grupos Recentes | R2: Museu Paraense Emílio Goeldi | S2: MPEG | T2: PA | U2: NO | V2: Brasil | W2: Museu Paraense Emílio Goeldi | X2: MPEG | Y2: PA | Z2: NO | AA2: Brasil | AB2: DCTI | AC2: COEBI | AD2: 27/06/2026 | AE2: 15:54:01 | AF2: 27/06/2026 | AG2: 15:54:21 | AH2: 4 | AI2: 443040 | AJ2: 44000 | AK2: 0 | AL2: 487040 | AM2: Museu Paraense Emílio Goeldi | AN2: MPEG | AO2: PA | AP2: NO | AQ2: Brasil | AR2: 8721994758453503 | AS2: 46202.465 | AT2: PCI2026 | AU2: Chamada CNPq/MCTI/FNDCT Nº 12/2026 - Programa PCI | AV2: Chamada: Chamada CNPq/MCTI/FNDCT Nº 12/2026 - Faixa 3: Projetos de Pesquisa vinculados a | AW2: 12/2026 | AX2: Chamada CNPq/MCTI/FNDCT Nº 12/2026 - Faixa 3: Projetos de Pesquisa vinculados a UPs Grandes (acima de 200 servidores) | AY2: 27/04/2026 | AZ2: 27/06/2026 | BA2: bonaldo@museu-goeldi.br | BB2: 402356/2026-8 | BC2: Alexandre Bragio Bonaldo | BD2: Museu Paraense Emílio Goeldi | BE2: MPEG | BF2: =IF(AND(BG2,BI2,BL2,BM2),TRUE,FALSE) -> TRUE | BG2: TRUE | BH2: 1999 | BI2: TRUE | BJ2: Faixa 3 | BK2: Faixa 3 (24 propostas) | BL2: TRUE | BM2: TRUE | BN2: TRUE | BO2: - Museu Paraense Emílio Goeldi: (Pesquisador Titular) - Museu Paraense Emílio Goeldi: (Servidor público - Curador das coleções de Arachnida e Myriapoda) - Instituto Butantan: (COLABORADOR - Colaborador) - Universidade Federal do Pará: (COLABORADOR - Professor Pós-Graduação em Zoologia) - Universidade Federal do Pará: (COLABORADOR - Vice-Coordenador Pós-Graduação Zoologia) - Universidade Federal do Pará: (COLABORADOR - Coordenador - Programa de PG em Zoologia) - Museo Argentino de Ciencias Naturales Bernardino Rivadavia: (em branco) | BP2: =IF(IFERROR(VLOOKUP(A2,[1]Planilha1!$A:$A,1,0),FALSE)=FALSE,FALSE,TRUE) -> TRUE
A3: 400950/2026-0 | B3: APQ | D3: 46204 | E3: 47664 | F3: 80777376504 | G3: Alfeu Joãozinho Sguarezi Filho | H3: http://lattes.cnpq.br/6603067354811112 | I3: Alfeu Joãozinho Sguarezi Filho | K3: Alfeu Joãozinho Sguarezi Filho, Luis Felipe Normandia Lourenço, Darlan Alexandria Fernandes, Alain Segundo Potts, Jefferson Souza Costa, Yuri de Oliveira Cota, Vitor da Silva Jorge, Angelo dos Santos Lunardi, Marco Estaban Rivera | L3: 5105890 | M3: Desenvolvimento de técnicas de controle para um conversor de potência aplicado na integração de fontes de energia renováveis a rede elétrica. | N3: PROGRAMA BASICO DE ENGENHARIA ELETRICA | O3: EE | P3: Engenharias | Q3: Eletrônica de Potência | R3: Universidade Federal do ABC | S3: UFABC | T3: SP | U3: SE | V3: Brasil | W3: Universidade Federal do ABC | X3: UFABC | Y3: SP | Z3: SE | AA3: Brasil | AB3: DCTI | AC3: COENG | AD3: 08/05/2026 | AE3: 10:09:48 | AF3: 08/05/2026 | AG3: 10:09:55 | AH3: 9 | AI3: 1304800 | AJ3: 130000 | AK3: 0 | AL3: 1434800 | AM3: Universidade Federal do ABC | AN3: UFABC | AO3: SP | AP3: SE | AQ3: Brasil | AR3: 6603067354811112 | AS3: 46202.465 | AT3: PCI2026 | AU3: Chamada CNPq/MCTI/FNDCT Nº 12/2026 - Programa PCI | AV3: Chamada: Chamada CNPq/MCTI/FNDCT Nº 12/2026 - Faixa 3: Projetos de Pesquisa vinculados a | AW3: 12/2026 | AX3: Chamada CNPq/MCTI/FNDCT Nº 12/2026 - Faixa 3: Projetos de Pesquisa vinculados a UPs Grandes (acima de 200 servidores) | AY3: 27/04/2026 | AZ3: 27/06/2026 | BA3: alfeu_sguarezi@yahoo.com.br | BB3: 400950/2026-0 | BC3: Alfeu Joãozinho Sguarezi Filho | BD3: Universidade Federal do ABC | BE3: UFABC | BF3: =IF(AND(BG3,BI3,BL3,BM3),TRUE,FALSE) -> FALSE | BG3: FALSE | BH3: 2010 | BI3: FALSE | BJ3: Faixa 3 | BK3: Faixa 3 (1 propostas) | BL3: TRUE | BM3: TRUE | BN3: TRUE | BO3: - Universidade Federal do ABC: (Servidor público - Professor Associado IV) - Sociedade Brasileira de Automática: (Membro comitê - Vice-coordenador Sistemas de Potência) - Universidade de São Paulo: (Docente PGEE - Docente PPGEE) - International Federation of Automatic Control: (Membro - Não há.) | BP3: =IF(IFERROR(VLOOKUP(A3,[1]Planilha1!$A:$A,1,0),FALSE)=FALSE,FALSE,TRUE) -> FALSE
A4: 401867/2026-9 | B4: APQ | D4: 46204 | E4: 47664 | F4: 02837590703 | G4: Aline Theodoro Toci | H4: http://lattes.cnpq.br/2923907838228544 | I4: Aline Theodoro Toci | K4: Aline Theodoro Toci, Rodrigo Sequinel, Fernando Augusto de Freitas, Rafaella Costa Bonugli Santos, Mayara Ali Dahrouj, Luana Estefani Knaul, Aldo Sindulfo Barboza Valdez | L4: 5116300 | M4: Perfil químico e biológico de canetas emagrecedoras a base de tirzepatida e retatrutida apreendidas na Triplice Fronteira (PY-BR-AR) | N4: PROGRAMA BASICO DE QUIMICA | O4: QU | P4: Ciências Exatas e da Terra | Q4: Química Analítica | R4: Universidade Federal da Integração Latino-Americana | S4: UNILA | T4: PR | U4: SU | V4: Brasil | W4: Universidade Federal da Integração Latino-Americana | X4: UNILA | Y4: PR | Z4: SU | AA4: Brasil | AB4: DCTI | AC4: COCQG | AD4: 23/06/2026 | AE4: 12:36:12 | AF4: 23/06/2026 | AG4: 13:49:10 | AH4: 5 | AI4: 461760 | AJ4: 60000 | AK4: 0 | AL4: 521760 | AM4: Universidade Federal da Integração Latino-Americana | AN4: UNILA | AO4: PR | AP4: SU | AQ4: Brasil | AR4: 2923907838228544 | AS4: 46202.465 | AT4: PCI2026 | AU4: Chamada CNPq/MCTI/FNDCT Nº 12/2026 - Programa PCI | AV4: Chamada: Chamada CNPq/MCTI/FNDCT Nº 12/2026 - Faixa 3: Projetos de Pesquisa vinculados a | AW4: 12/2026 | AX4: Chamada CNPq/MCTI/FNDCT Nº 12/2026 - Faixa 3: Projetos de Pesquisa vinculados a UPs Grandes (acima de 200 servidores) | AY4: 27/04/2026 | AZ4: 27/06/2026 | BA4: attoci@yahoo.com.br | BB4: 401867/2026-9 | BC4: Aline Theodoro Toci | BD4: Universidade Federal da Integração Latino-Americana | BE4: UNILA | BF4: =IF(AND(BG4,BI4,BL4,BM4),TRUE,FALSE) -> FALSE | BG4: FALSE | BH4: 2010 | BI4: FALSE | BJ4: Faixa 3 | BK4: Faixa 3 (4 propostas) | BL4: TRUE | BM4: TRUE | BN4: TRUE | BO4: - Universidade Federal da Integração Latino-Americana: (Servidor público - Adjunto A) - Fundação Araucária de Apoio ao Desenvolvimento Científico e Tecnológico: (Membro de comitê assessor) | BP4: =IF(IFERROR(VLOOKUP(A4,[1]Planilha1!$A:$A,1,0),FALSE)=FALSE,FALSE,TRUE) -> FALSE
A5: 402099/2026-5 | B5: APQ | D5: 46204 | E5: 47664 | F5: 72842792653 | G5: Ana Lúcia da Costa Prudente | H5: http://lattes.cnpq.br/1008924786363328 | I5: Ana Lúcia da Costa Prudente | K5: Ana Lúcia da Costa Prudente, Roberta Graboski Mendes, Luciano Nicolás Naka, Kaelle Vaccari Silva Caldeira, Patricia Rodrigues da Silva, João Fabricio de Melo Sarmento, Bruna Mirely da Silva Costa, Giovanna Olivarez Couto | L5: 5116591 | M5: Origem e Diversificação de Vertebrados Terrestres na Amazônia: Uma Abordagem Integrativa | N5: PROGRAMA BASICO DE ZOOLOGIA E RECURSOS PESQUEIROS DE AGUAS INTERIORES | O5: ZO | P5: Ciências Biológicas | Q5: Taxonomia dos Grupos Recentes | R5: Museu Paraense Emílio Goeldi | S5: MPEG | T5: PA | U5: NO | V5: Brasil | W5: Museu Paraense Emílio Goeldi | X5: MPEG | Y5: PA | Z5: NO | AA5: Brasil | AB5: DCTI | AC5: COEBI | AD5: 26/06/2026 | AE5: 15:56:04 | AF5: 27/06/2026 | AG5: 09:52:34 | AH5: 11 | AI5: 1054820 | AJ5: 149658.89 | AK5: 0 | AL5: 1204478.9 | AM5: Museu Paraense Emílio Goeldi | AN5: MPEG | AO5: PA | AP5: NO | AQ5: Brasil | AR5: 1008924786363328 | AS5: 46202.465 | AT5: PCI2026 | AU5: Chamada CNPq/MCTI/FNDCT Nº 12/2026 - Programa PCI | AV5: Chamada: Chamada CNPq/MCTI/FNDCT Nº 12/2026 - Faixa 3: Projetos de Pesquisa vinculados a | AW5: 12/2026 | AX5: Chamada CNPq/MCTI/FNDCT Nº 12/2026 - Faixa 3: Projetos de Pesquisa vinculados a UPs Grandes (acima de 200 servidores) | AY5: 27/04/2026 | AZ5: 27/06/2026 | BA5: prudente@museu-goeldi.br | BB5: 402099/2026-5 | BC5: Ana Lúcia da Costa Prudente | BD5: Museu Paraense Emílio Goeldi | BE5: MPEG | BF5: =IF(AND(BG5,BI5,BL5,BM5),TRUE,FALSE) -> TRUE | BG5: TRUE | BH5: 1998 | BI5: TRUE | BJ5: Faixa 3 | BK5: Faixa 3 (24 propostas) | BL5: TRUE | BM5: TRUE | BN5: TRUE | BO5: - Museu Paraense Emílio Goeldi: (Servidor público - Pesquisador Titular) | BP5: =IF(IFERROR(VLOOKUP(A5,[1]Planilha1!$A:$A,1,0),FALSE)=FALSE,FALSE,TRUE) -> TRUE
A6: 401036/2026-0 | B6: APQ | D6: 46204 | E6: 47664 | F6: 56038496220 | G6: Ana Lucia M Wanzeller | H6: http://lattes.cnpq.br/8983339131944366 | I6: Ana Lucia M Wanzeller | K6: Ana Lucia M Wanzeller, Anderson Bentes de Lima, Ana Cecília Ribeiro Cruz, Ana Claudia da Silva Ribeiro, Joaquim Pinto Nunes Neto, Paula Renata Lima Machado Farias, Lívia Caricio Martins, Livia Medeiros Neves Casseb, Valéria | L6: 5111149 | M6: Nanotecnologia farmacêutica aplicada ao desenvolvimento de antivirais contra arbovírus: avaliação in vitro e in vivo de nanoemulsões contendo óleos essenciais da biodiversidade amazônica. | N6: PROGRAMA BASICO DE MICROBIOLOGIA | O6: MP | P6: Ciências Biológicas | Q6: Virologia | R6: Instituto Evandro Chagas | S6: IEC | T6: PA | U6: NO | V6: Brasil | W6: Instituto Evandro Chagas | X6: IEC | Y6: PA | Z6: NO | AA6: Brasil | AB6: DCTI | AC6: COBIO | AD6: 23/05/2026 | AE6: 09:22:51 | AF6: 23/05/2026 | AG6: 09:23:00 | AH6: 8 | AI6: 1394640 | AJ6: 104200 | AK6: 0 | AL6: 1498840 | AM6: Instituto Evandro Chagas | AN6: IEC | AO6: PA | AP6: NO | AQ6: Brasil | AR6: 8983339131944366 | AS6: 46202.465 | AT6: PCI2026 | AU6: Chamada CNPq/MCTI/FNDCT Nº 12/2026 - Programa PCI | AV6: Chamada: Chamada CNPq/MCTI/FNDCT Nº 12/2026 - Faixa 3: Projetos de Pesquisa vinculados a | AW6: 12/2026 | AX6: Chamada CNPq/MCTI/FNDCT Nº 12/2026 - Faixa 3: Projetos de Pesquisa vinculados a UPs Grandes (acima de 200 servidores) | AY6: 27/04/2026 | AZ6: 27/06/2026 | BA6: anawanzeller@iec.gov.br | BB6: 401036/2026-0 | BC6: Ana Lucia M Wanzeller | BD6: Instituto Evandro Chagas | BE6: IEC | BF6: =IF(AND(BG6,BI6,BL6,BM6),TRUE,FALSE) -> FALSE | BG6: FALSE | BH6: 2017 | BI6: FALSE | BJ6: Faixa 3 | BK6: Faixa 3 (1 propostas) | BL6: TRUE | BM6: TRUE | BN6: TRUE | BO6: - Instituto Evandro Chagas: (Servidor público - Pesquisadora em Saúde Pública) - Instituto Evandro Chagas: (Servidor público - Pesquisadora em Saúde Pública) - Instituto Evandro Chagas: (VICE COORDENAÇÃO PPGV - VICE-COORDENADORA DO PPGV) - Instituto Evandro Chagas: (em branco) | BP6: =IF(IFERROR(VLOOKUP(A6,[1]Planilha1!$A:$A,1,0),FALSE)=FALSE,FALSE,TRUE) -> FALSE
A7: 401028/2026-7 | B7: APQ | D7: 46204 | E7: 47664 | F7: 11464843805 | G7: Anderson Zanardi de Freitas | H7: http://lattes.cnpq.br/7935699829401769 | I7: Anderson Zanardi de Freitas | K7: Anderson Zanardi de Freitas, Anselmo Sigari Moriscot, Niklaus Ursus Wetter, Patrick Jack Spencer, Daniel Perez Vieira, André Mourão Batista, Martha Simões Ribeiro | L7: 5110772 | M7: Capacitação Científica e Tecnológica em Espectroscopia Raman em Nanoescala Aplicada a Sistemas Biológicos | N7: PROGRAMA BASICO DE FISICA | O7: FA | P7: Ciências Exatas e da Terra | Q7: Prop. Óticas e Espectrosc. da Mat. Condens; Outras Inter. da | R7: COMISSAO NACIONAL DE ENERGIA NUCLEAR | S7: CNEN | T7: RJ | U7: SE | V7: Brasil | W7: COMISSAO NACIONAL DE ENERGIA NUCLEAR | X7: CNEN | Y7: RJ | Z7: SE | AA7: Brasil | AB7: DCTI | AC7: COCEC | AD7: 22/05/2026 | AE7: 13:03:36 | AF7: 22/05/2026 | AG7: 14:04:55 | AH7: 6 | AI7: 1272960 | AJ7: 119000 | AK7: 0 | AL7: 1391960 | AR7: 7935699829401769 | AS7: 46202.465 | AT7: PCI2026 | AU7: Chamada CNPq/MCTI/FNDCT Nº 12/2026 - Programa PCI | AV7: Chamada: Chamada CNPq/MCTI/FNDCT Nº 12/2026 - Faixa 3: Projetos de Pesquisa vinculados a | AW7: 12/2026 | AX7: Chamada CNPq/MCTI/FNDCT Nº 12/2026 - Faixa 3: Projetos de Pesquisa vinculados a UPs Grandes (acima de 200 servidores) | AY7: 27/04/2026 | AZ7: 27/06/2026 | BA7: freitas.az@gmail.com | BB7: 401028/2026-7 | BC7: Anderson Zanardi de Freitas | BD7: COMISSAO NACIONAL DE ENERGIA NUCLEAR | BE7: CNEN | BF7: =IF(AND(BG7,BI7,BL7,BM7),TRUE,FALSE) -> TRUE | BG7: TRUE | BH7: 2007 | BI7: TRUE | BJ7: Faixa 3 | BK7: Faixa 3 (32 propostas) | BL7: TRUE | BM7: TRUE | BN7: TRUE | BO7: - Instituto de Pesquisas Enegéticas e Nucleares: (Servidor público - Tecnologista) | BP7: =IF(IFERROR(VLOOKUP(A7,[1]Planilha1!$A:$A,1,0),FALSE)=FALSE,FALSE,TRUE) -> TRUE
A8: 402246/2026-8 | B8: APQ | D8: 46204 | E8: 47664 | F8: 05462482680 | G8: Andre Augusto Campagnole dos Santos | H8: http://lattes.cnpq.br/4652863024621768 | I8: Andre Augusto Campagnole dos Santos | K8: Andre Augusto Campagnole dos Santos, Graiciany de Paula Barros, Vitor Vasconcelos Araújo Silva, Wesley Cecilio silva, Higor Fabiano Pereira de Castro, Edson Ribeiro, Eduardo Tadeu Stehling Saraiva, Claudio Cunha Lopes, | L8: 5116744 | M8: Investigação Numérico-Experimental de Protótipos Fabricados por Manufatura Aditiva para Desenvolvimento e Nacionalização de Componentes de Reatores SMR | N8: PROGRAMA BASICO DE ENGENHARIA NUCLEAR | O8: EN | P8: Engenharias | Q8: Transferência de Calor em Reatores | R8: COMISSAO NACIONAL DE ENERGIA NUCLEAR | S8: CNEN | T8: RJ | U8: SE | V8: Brasil | W8: COMISSAO NACIONAL DE ENERGIA NUCLEAR | X8: CNEN | Y8: RJ | Z8: SE | AA8: Brasil | AB8: DCTI | AC8: COBEN | AD8: 26/06/2026 | AE8: 17:25:01 | AF8: 27/06/2026 | AG8: 10:01:36 | AH8: 3 | AI8: 542880 | AJ8: 78416 | AK8: 0 | AL8: 621296 | AM8: COMISSAO NACIONAL DE ENERGIA NUCLEAR | AN8: CNEN | AO8: RJ | AP8: SE | AQ8: Brasil | AR8: 4652863024621768 | AS8: 46202.465 | AT8: PCI2026 | AU8: Chamada CNPq/MCTI/FNDCT Nº 12/2026 - Programa PCI | AV8: Chamada: Chamada CNPq/MCTI/FNDCT Nº 12/2026 - Faixa 3: Projetos de Pesquisa vinculados a | AW8: 12/2026 | AX8: Chamada CNPq/MCTI/FNDCT Nº 12/2026 - Faixa 3: Projetos de Pesquisa vinculados a UPs Grandes (acima de 200 servidores) | AY8: 27/04/2026 | AZ8: 27/06/2026 | BA8: acampagnole@yahoo.com.br | BB8: 402246/2026-8 | BC8: Andre Augusto Campagnole dos Santos | BD8: COMISSAO NACIONAL DE ENERGIA NUCLEAR | BE8: CNEN | BF8: =IF(AND(BG8,BI8,BL8,BM8),TRUE,FALSE) -> TRUE | BG8: TRUE | BH8: 2012 | BI8: TRUE | BJ8: Faixa 3 | BK8: Faixa 3 (32 propostas) | BL8: TRUE | BM8: TRUE | BN8: TRUE | BO8: - COMISSAO NACIONAL DE ENERGIA NUCLEAR: (Pesquisador) - COMISSAO NACIONAL DE ENERGIA NUCLEAR: (Professor - Professor permanente) - COMISSAO NACIONAL DE ENERGIA NUCLEAR: (Coordenador da pós-graduação - Coordenador da pós-graduação CDTN) - COMISSAO NACIONAL DE ENERGIA NUCLEAR: (Servidor público - Chefe substituto DIFES - Divisão de Formação) - Comissão Nacional de Energia Nuclear: (Membro de comitê assessor) | BP8: =IF(IFERROR(VLOOKUP(A8,[1]Planilha1!$A:$A,1,0),FALSE)=FALSE,FALSE,TRUE) -> TRUE
A9: 402067/2026-6 | B9: APQ | D9: 46204 | E9: 47664 | F9: 07730923742 | G9: André dos Santos Bragança Gil | H9: http://lattes.cnpq.br/4874787664520093 | I9: André dos Santos Bragança Gil | K9: André dos Santos Bragança Gil, Julia Meirelles, Josiane Santana Monteiro, Adriene Mayra da Silva Soares, Jadson José Souza de Oliveira, Bárbara Dunck Oliveira, Flavia Machado Durgante, Caroline da Cruz Vasconcelos | L9: 5116558 | M9: Flora e Funga da Floresta Nacional de Caxiuanã: Taxonomia, Fortalecimento de Acervos e Inovação Tecnológica para a Conservação da Biodiversidade Amazônica | N9: PROGRAMA BASICO DE BOTANICA | O9: BO | P9: Ciências Biológicas | Q9: Taxonomia Vegetal | R9: Museu Paraense Emílio Goeldi | S9: MPEG | T9: PA | U9: NO | V9: Brasil | W9: Museu Paraense Emílio Goeldi | X9: MPEG | Y9: PA | Z9: NO | AA9: Brasil | AB9: DCTI | AC9: COEBI | AD9: 26/06/2026 | AE9: 13:06:04 | AF9: 27/06/2026 | AG9: 09:50:41 | AH9: 14 | AI9: 1041040 | AJ9: 146561.05 | AK9: 0 | AL9: 1187601.1 | AM9: Museu Paraense Emílio Goeldi | AN9: MPEG | AO9: PA | AP9: NO | AQ9: Brasil | AR9: 4874787664520093 | AS9: 46202.465 | AT9: PCI2026 | AU9: Chamada CNPq/MCTI/FNDCT Nº 12/2026 - Programa PCI | AV9: Chamada: Chamada CNPq/MCTI/FNDCT Nº 12/2026 - Faixa 3: Projetos de Pesquisa vinculados a | AW9: 12/2026 | AX9: Chamada CNPq/MCTI/FNDCT Nº 12/2026 - Faixa 3: Projetos de Pesquisa vinculados a UPs Grandes (acima de 200 servidores) | AY9: 27/04/2026 | AZ9: 27/06/2026 | BA9: asbgil@yahoo.com.br | BB9: 402067/2026-6 | BC9: André dos Santos Bragança Gil | BD9: Museu Paraense Emílio Goeldi | BE9: MPEG | BF9: =IF(AND(BG9,BI9,BL9,BM9),TRUE,FALSE) -> TRUE | BG9: TRUE | BH9: 2012 | BI9: TRUE | BJ9: Faixa 3 | BK9: Faixa 3 (24 propostas) | BL9: TRUE | BM9: TRUE | BN9: TRUE | BO9: - Museu Paraense Emílio Goeldi: (Servidor público - Pesquisador Titular III) - Universidade Federal Rural da Amazônia/Museu Paraense Emílio Goeldi: (Docente permanente - Professor orientador) - Instituto Nacional de Pesquisas da Amazônia: (COLABORADOR - Colaborador no projeto HerbSpectra-Amazônia) | BP9: =IF(IFERROR(VLOOKUP(A9,[1]Planilha1!$A:$A,1,0),FALSE)=FALSE,FALSE,TRUE) -> TRUE
A10: 401115/2026-7 | B10: APQ | D10: 46204 | E10: 47664 | F10: 02786029678 | G10: André Luís Silva | H10: http://lattes.cnpq.br/3393832875052048 | I10: André Luís Silva | K10: André Luís Silva, Pamella Thaís Magalhães Ferreira, Daniel Magalhães Bicalho, André Fonseca Amâncio, Abelard Ramos Fernandes, Saulo Hallah | L10: 5114814 | M10: SISTEMA DE DIAGNÓSTICO DE MATURIDADE E SOBREVIVÊNCIA : DESENVOLVIMENTO, DEMONSTRAÇÃO E TRANSFERÊNCIA DE TECNOLOGIA DE GESTÃO PARA INCUBADORAS DE EMPRESAS BRASILEIRAS | N10: PROGRAMA BASICO DE ADMINISTRACAO | O10: AE | P10: Ciências Sociais Aplicadas | Q10: Administração de Setores Específicos | R10: Universidade Federal de Ouro Preto | S10: UFOP | T10: MG | U10: SE | V10: Brasil | W10: Universidade Federal de Ouro Preto | X10: UFOP | Y10: MG | Z10: SE | AA10: Brasil | AB10: DCTI | AC10: COSAE | AD10: 26/05/2026 | AE10: 15:11:21 | AF10: 27/05/2026 | AG10: 16:56:19 | AH10: 5 | AI10: 1110720 | AJ10: 61000 | AK10: 0 | AL10: 1171720 | AM10: Universidade Federal de Ouro Preto | AN10: UFOP | AO10: MG | AP10: SE | AQ10: Brasil | AR10: 3393832875052048 | AS10: 46202.465 | AT10: PCI2026 | AU10: Chamada CNPq/MCTI/FNDCT Nº 12/2026 - Programa PCI | AV10: Chamada: Chamada CNPq/MCTI/FNDCT Nº 12/2026 - Faixa 3: Projetos de Pesquisa vinculados a | AW10: 12/2026 | AX10: Chamada CNPq/MCTI/FNDCT Nº 12/2026 - Faixa 3: Projetos de Pesquisa vinculados a UPs Grandes (acima de 200 servidores) | AY10: 27/04/2026 | AZ10: 27/06/2026 | BA10: andre.silva@ufop.edu.br | BB10: 401115/2026-7 | BC10: André Luís Silva | BD10: Universidade Federal de Ouro Preto | BE10: UFOP | BF10: =IF(AND(BG10,BI10,BL10,BM10),TRUE,FALSE) -> FALSE | BG10: FALSE | BH10: 2016 | BI10: FALSE | BJ10: Faixa 3 | BK10: Faixa 3 (1 propostas) | BL10: TRUE | BM10: TRUE | BN10: TRUE | BO10: - Universidade Federal de Ouro Preto: (Servidor público - Professor Associado) - Parque Tecnológico de Belo Horizonte: (COLABORADOR - Pesquisador) | BP10: =IF(IFERROR(VLOOKUP(A10,[1]Planilha1!$A:$A,1,0),FALSE)=FALSE,FALSE,TRUE) -> FALSE
A11: 401992/2026-8 | B11: APQ | D11: 46204 | E11: 47664 | F11: 42437784268 | G11: Anna Luiza Ilkiu Borges Benkendorff | H11: http://lattes.cnpq.br/4847808223159236 | I11: Anna Luiza Ilkiu Borges Benkendorff | K11: Anna Luiza Ilkiu Borges Benkendorff, Ana Carla Feio dos Santos, Paula Godinho Ribeiro, Fúvio Rubens Oliveira da Silva, Sâmia Batista e Silva, Manolo Cleiton Costa de Freitas, Patricia Magalhães Pereira Silva, Flavia Machado | L11: 5116475 | M11: Consolidação da Pesquisa e Inovação do Museu Goeldi na Amazônia: Capacitação Tecnológica para o Manejo e Conservação da FLONA de Caxiuanã | N11: Programa Especial de Biotecnologia e Recursos Genéticos - COBRG | O11: BI | P11: Ciências Biológicas | Q11: Biotecnologia Ambiental e Recursos Naturais | R11: Museu Paraense Emílio Goeldi | S11: MPEG | T11: PA | U11: NO | V11: Brasil | W11: Museu Paraense Emílio Goeldi | X11: MPEG | Y11: PA | Z11: NO | AA11: Brasil | AB11: DCTI | AC11: COBEN | AD11: 25/06/2026 | AE11: 16:33:38 | AF11: 25/06/2026 | AG11: 16:50:30 | AH11: 10 | AI11: 1299300 | AJ11: 130000 | AK11: 0 | AL11: 1429300 | AM11: Museu Paraense Emílio Goeldi | AN11: MPEG | AO11: PA | AP11: NO | AQ11: Brasil | AR11: 4847808223159236 | AS11: 46202.465 | AT11: PCI2026 | AU11: Chamada CNPq/MCTI/FNDCT Nº 12/2026 - Programa PCI | AV11: Chamada: Chamada CNPq/MCTI/FNDCT Nº 12/2026 - Faixa 3: Projetos de Pesquisa vinculados a | AW11: 12/2026 | AX11: Chamada CNPq/MCTI/FNDCT Nº 12/2026 - Faixa 3: Projetos de Pesquisa vinculados a UPs Grandes (acima de 200 servidores) | AY11: 27/04/2026 | AZ11: 27/06/2026 | BA11: ilkiu-borges@museu-goeldi.br | BB11: 401992/2026-8 | BC11: Anna Luiza Ilkiu Borges Benkendorff | BD11: Museu Paraense Emílio Goeldi | BE11: MPEG | BF11: =IF(AND(BG11,BI11,BL11,BM11),TRUE,FALSE) -> TRUE | BG11: TRUE | BH11: 2005 | BI11: TRUE | BJ11: Faixa 3 | BK11: Faixa 3 (24 propostas) | BL11: TRUE | BM11: TRUE | BN11: TRUE | BO11: - Museu Paraense Emílio Goeldi: (Servidor público - Editora Associada de Botânica) - Museu Paraense Emílio Goeldi: (Servidor público - Pesquisador Titular III) - Universidade Federal Rural da Amazônia: (Professor da Pós-Graduação) - Universidade Federal Rural da Amazônia: (COLABORADOR - Coordenadora de Pós-graduação) | BP11: =IF(IFERROR(VLOOKUP(A11,[1]Planilha1!$A:$A,1,0),FALSE)=FALSE,FALSE,TRUE) -> TRUE
A12: 401313/2026-3 | B12: APQ | D12: 46204 | E12: 47664 | F12: 87302128715 | G12: Antônio Carlos de Abreu Mól | H12: http://lattes.cnpq.br/1168989222280325 | I12: Antônio Carlos de Abreu Mól | K12: Antônio Carlos de Abreu Mól, Cláudio Márcio do Nascimento Abreu Pereira, Cláudio Henrique dos Santos Grecco, Paulo Victor Rodrigues de Carvalho, Eugenio Rangel Marins, Ana Paula Legey de Siqueira, Sheila da Silva Ferreira | L12: 5115674 | M12: CIDADE VIRTUAL DA CIÊNCIA: METODOLOGIAS EDUCATIVAS PARA POPULARIZAÇÃO DA CIÊNCIA NUCLEAR E FORMAÇÃO DE EDUCADORES | N12: PROGRAMA BASICO DE ENGENHARIA NUCLEAR | O12: EN | P12: Engenharias | Q12: Tecnologia dos Reatores | R12: Instituto de Engenharia Nuclear | S12: IEN/CNEN | T12: RJ | U12: SE | V12: Brasil | W12: Instituto de Engenharia Nuclear | X12: IEN/CNEN | Y12: RJ | Z12: SE | AA12: Brasil | AB12: DCTI | AC12: COBEN | AD12: 16/06/2026 | AE12: 17:34:33 | AF12: 16/06/2026 | AG12: 17:34:40 | AH12: 6 | AI12: 1048320 | AJ12: 120000 | AK12: 0 | AL12: 1168320 | AM12: COMISSAO NACIONAL DE ENERGIA NUCLEAR | AN12: CNEN | AO12: RJ | AP12: SE | AQ12: Brasil | AR12: 1168989222280325 | AS12: 46202.465 | AT12: PCI2026 | AU12: Chamada CNPq/MCTI/FNDCT Nº 12/2026 - Programa PCI | AV12: Chamada: Chamada CNPq/MCTI/FNDCT Nº 12/2026 - Faixa 3: Projetos de Pesquisa vinculados a | AW12: 12/2026 | AX12: Chamada CNPq/MCTI/FNDCT Nº 12/2026 - Faixa 3: Projetos de Pesquisa vinculados a UPs Grandes (acima de 200 servidores) | AY12: 27/04/2026 | AZ12: 27/06/2026 | BA12: antonio.mol@ien.gov.br | BB12: 401313/2026-3 | BC12: Antônio Carlos de Abreu Mól | BD12: Instituto de Engenharia Nuclear | BE12: IEN/CNEN | BF12: =IF(AND(BG12,BI12,BL12,BM12),TRUE,FALSE) -> TRUE | BG12: TRUE | BH12: 2002 | BI12: TRUE | BJ12: Faixa 3 | BK12: Faixa 3 (2 propostas) | BL12: TRUE | BM12: TRUE | BN12: TRUE | BO12: - COMISSAO NACIONAL DE ENERGIA NUCLEAR: (Servidor público - Tecnologista Sênior,) - COMISSAO NACIONAL DE ENERGIA NUCLEAR: (Servidor público - Pro-Reitor de Ensino) - COMISSAO NACIONAL DE ENERGIA NUCLEAR: (Servidor público - Chefe de Divisão de Ensino) - Fundação Carlos Chagas Filho de Amparo à Pesquisa do Estado do RJ: (COLABORADOR - consultor ad hoc (Ciência da Computação)) - Fundação Carlos Chagas Filho de Amparo à Pesquisa do Estado do RJ: (Pesquisador - Jovem Cientista do Estado do RJ) - Fundação Carlos Chagas Filho de Amparo à Pesquisa do Estado do RJ: (Pesquisador - Coordenador Projeto Pesquisa) - (CNPq) Conselho Nacional de Desenvolvimento Científico e Tecnológico: (Pesquisador - Coordenador Projeto Pesquisa) - (CNPq) Conselho Nacional de Desenvolvimento Científico e Tecnológico: (Pesquisador - Acessor Ad-hoc) - (FAPERJ) Fundação Carlos Chagas Filho de Amparo à Pesq. do Estado do Rio de: (Membro de comitê assessor) - (UGF) universdade gama filho: (Membro de comitê assessor) - (UGF) universdade gama filho: (Membro de comitê assessor) - (CNPq) Conselho Nacional de Desenvolvimento Científico e Tecnológico: (Membro de comitê assessor) - Centro Universitário Carioca: (CELETISTA - PROFESSOR_TITULAR) - Universidade Federal do Rio de Janeiro: (COLABORADOR - colaborador) - Instituto de Ciencia e Tecnologia de Reatores Modulares e Inovadores: (vice-coordenador - Pesquisador) | BP12: =IF(IFERROR(VLOOKUP(A12,[1]Planilha1!$A:$A,1,0),FALSE)=FALSE,FALSE,TRUE) -> TRUE
A13: 402370/2026-0 | B13: APQ | D13: 46204 | E13: 47664 | F13: 80900402849 | G13: Artur Wilson Carbonari | H13: http://lattes.cnpq.br/0983858173807551 | I13: Artur Wilson Carbonari | K13: Artur Wilson Carbonari, Rajendra Narain Saxena, Frederico Antonio Genezini, Gabriel Adolfo Cabrera Pasca, Ronaldo Domingues Mansano, Levy Scalise Maciel, Wanderson Lobato Ferreira, Luciano Fabrício Dias Pereira, | L13: 5116868 | M13: Capacitação Institucional em Tecnologias Nucleares Aplicadas a Semicondutores: Produção de Silício Tipo-N Dopado por Transmutação Neutrônica (NTD) para Dispositivos Fotovoltaicos e Detectores de Radiação de Alta Eficiência | N13: PROGRAMA BASICO DE ENGENHARIA NUCLEAR | O13: EN | P13: Engenharias | Q13: Aplicações Industriais de Radioisótopos | R13: Instituto de Pesquisas Energéticas e Nucleares | S13: IPEN/CNEN | T13: SP | U13: SE | V13: Brasil | W13: Instituto de Pesquisas Energéticas e Nucleares | X13: IPEN/CNEN | Y13: SP | Z13: SE | AA13: Brasil | AB13: DCTI | AC13: COBEN | AD13: 27/06/2026 | AE13: 17:56:32 | AF13: 27/06/2026 | AG13: 17:56:38 | AH13: 5 | AI13: 982800 | AJ13: 130670 | AK13: 0 | AL13: 1113470 | AR13: 0983858173807551 | AS13: 46202.465 | AT13: PCI2026 | AU13: Chamada CNPq/MCTI/FNDCT Nº 12/2026 - Programa PCI | AV13: Chamada: Chamada CNPq/MCTI/FNDCT Nº 12/2026 - Faixa 3: Projetos de Pesquisa vinculados a | AW13: 12/2026 | AX13: Chamada CNPq/MCTI/FNDCT Nº 12/2026 - Faixa 3: Projetos de Pesquisa vinculados a UPs Grandes (acima de 200 servidores) | AY13: 27/04/2026 | AZ13: 27/06/2026 | BA13: artur.wilson.carbonari@cern.ch | BB13: 402370/2026-0 | BC13: Artur Wilson Carbonari | BD13: Instituto de Pesquisas Energéticas e Nucleares | BE13: IPEN/CNEN | BF13: =IF(AND(BG13,BI13,BL13,BM13),TRUE,FALSE) -> FALSE | BG13: TRUE | BH13: 1992 | BI13: FALSE | BJ13: Faixa 3 | BK13: Faixa 3 (6 propostas) | BL13: TRUE | BM13: TRUE | BN13: TRUE | BO13: - Instituto de Pesquisas Energéticas e Nucleares: (Servidor público - PROFESSOR_TITULAR) - Instituto de Pesquisas Energéticas e Nucleares: (Servidor público - Pesquisador titular U III) - Conselho Nacional de Desenvolvimento Científico e Tecnológico: (OUTRO - pesquisador 1C) - Agencia Nacional de Promocion Cientifica y Tecnologica: (OUTRO - Outro (especifique) consultor ad hoc) - Universidade de São Paulo: (OUTRO - PROFESSOR_TITULAR) - European Organization for Nuclear Research: (COLABORADOR - Team leader) - COMISSAO NACIONAL DE ENERGIA NUCLEAR: (em branco) | BP13: =IF(IFERROR(VLOOKUP(A13,[1]Planilha1!$A:$A,1,0),FALSE)=FALSE,FALSE,TRUE) -> FALSE
A14: 402102/2026-6 | B14: APQ | D14: 46204 | E14: 47664 | F14: 38692799823 | G14: Augusto Nobre Gonçalves | H14: http://lattes.cnpq.br/1557063709034165 | I14: Augusto Nobre Gonçalves | K14: Augusto Nobre Gonçalves, Victor Leal Fernandes de Mello Pereira, Haline Dugolin Ceccato, Felipe Andre Mayer Silva, Cecília Vianna Pinheiro, Caroline Modica Custódio, Usama Ahmad, Ana Clara de Araujo Sousa, Fabio Ramos | L14: 5116594 | M14: Dos poliedros de coordenação aos quasicristais: Desenvolvimento de plataforma computacional para análise da complexidade estrutural de sólidos para inovação em caracterização de minerais estratégicos | N14: Programa Basico de Geociência | O14: GC | P14: Ciências Exatas e da Terra | Q14: Mineralogia | R14: Universidade de Brasília | S14: UnB | T14: DF | U14: CO | V14: Brasil | W14: Universidade de Brasília | X14: UnB | Y14: DF | Z14: CO | AA14: Brasil | AB14: DCTI | AC14: COCQG | AD14: 27/06/2026 | AE14: 01:43:58 | AF14: 27/06/2026 | AG14: 09:52:48 | AH14: 8 | AI14: 506640 | AJ14: 73181.33 | AK14: 0 | AL14: 579821.33 | AM14: Universidade de Brasília | AN14: UnB | AO14: DF | AP14: CO | AQ14: Brasil | AR14: 1557063709034165 | AS14: 46202.465 | AT14: PCI2026 | AU14: Chamada CNPq/MCTI/FNDCT Nº 12/2026 - Programa PCI | AV14: Chamada: Chamada CNPq/MCTI/FNDCT Nº 12/2026 - Faixa 3: Projetos de Pesquisa vinculados a | AW14: 12/2026 | AX14: Chamada CNPq/MCTI/FNDCT Nº 12/2026 - Faixa 3: Projetos de Pesquisa vinculados a UPs Grandes (acima de 200 servidores) | AY14: 27/04/2026 | AZ14: 27/06/2026 | BA14: nobre.augusto@gmail.com | BB14: 402102/2026-6 | BC14: Augusto Nobre Gonçalves | BD14: Universidade de Brasília | BE14: UnB | BF14: =IF(AND(BG14,BI14,BL14,BM14),TRUE,FALSE) -> FALSE | BG14: FALSE | BH14: 2020 | BI14: FALSE | BJ14: Faixa 3 | BK14: Faixa 3 (1 propostas) | BL14: TRUE | BM14: TRUE | BN14: TRUE | BO14: - Universidade de Brasília: (Servidor público - Professor Assistente A) | BP14: =IF(IFERROR(VLOOKUP(A14,[1]Planilha1!$A:$A,1,0),FALSE)=FALSE,FALSE,TRUE) -> FALSE
A15: 401010/2026-0 | B15: APQ | D15: 46204 | E15: 47664 | F15: 02755828684 | G15: Bruno Melo Mendes | H15: http://lattes.cnpq.br/7016638154017973 | I15: Bruno Melo Mendes | K15: Bruno Melo Mendes, Tarcisio Passos Ribeiro de Campos, Marco Aurélio de Sousa Lacerda, Bernardo Nunes Borges de Lima, Alberto Mizrahy Campos | L15: 5110015 | M15: Investigação da Técnica de Seleção Espectral Ressonante para Produção Radioisotópica e Redução de Radiotoxicidade de Radionuclideos | N15: PROGRAMA BASICO DE ENGENHARIA NUCLEAR | O15: EN | P15: Engenharias | Q15: Produção de Radioisótopos | R15: Centro de Desenvolvimento da Tecnologia Nuclear | S15: CDTN/CNEN | T15: MG | U15: SE | V15: Brasil | W15: Centro de Desenvolvimento da Tecnologia Nuclear | X15: CDTN/CNEN | Y15: MG | Z15: SE | AA15: Brasil | AB15: DCTI | AC15: COBEN | AD15: 20/05/2026 | AE15: 07:22:04 | AF15: 20/05/2026 | AG15: 12:01:59 | AH15: 3 | AI15: 583700 | AJ15: 59800 | AK15: 0 | AL15: 643500 | AR15: 7016638154017973 | AS15: 46202.465 | AT15: PCI2026 | AU15: Chamada CNPq/MCTI/FNDCT Nº 12/2026 - Programa PCI | AV15: Chamada: Chamada CNPq/MCTI/FNDCT Nº 12/2026 - Faixa 3: Projetos de Pesquisa vinculados a | AW15: 12/2026 | AX15: Chamada CNPq/MCTI/FNDCT Nº 12/2026 - Faixa 3: Projetos de Pesquisa vinculados a UPs Grandes (acima de 200 servidores) | AY15: 27/04/2026 | AZ15: 27/06/2026 | BA15: bmelom@hotmail.com | BB15: 401010/2026-0 | BC15: Bruno Melo Mendes | BD15: Centro de Desenvolvimento da Tecnologia Nuclear | BE15: CDTN/CNEN | BF15: =IF(AND(BG15,BI15,BL15,BM15),TRUE,FALSE) -> FALSE | BG15: TRUE | BH15: 2017 | BI15: FALSE | BJ15: Faixa 3 | BK15: Faixa 3 (2 propostas) | BL15: TRUE | BM15: TRUE | BN15: TRUE | BO15: - Centro de Desenvolvimento da Tecnologia Nuclear da CNEN: (Servidor público - Pesquisador) | BP15: =IF(IFERROR(VLOOKUP(A15,[1]Planilha1!$A:$A,1,0),FALSE)=FALSE,FALSE,TRUE) -> FALSE
A16: 402015/2026-6 | B16: APQ | D16: 46204 | E16: 47664 | F16: 16515740816 | G16: Caio Augusto dos Santos Coelho | H16: http://lattes.cnpq.br/4978912302419377 | I16: Caio Augusto dos Santos Coelho | K16: Caio Augusto dos Santos Coelho, Danielson Jorge Delgado Neves, Fabio Pinto da Rocha, Diogo Alessandro Arsego, Jose Alberto da Silva Ferreira, Luciana dos Santos Machado Carvalho, Eduardo Batista de Moraes Barbosa, Andre | L16: 5116505 | M16: Fortalecendo o sistema brasileiro de monitoramento e previsão climática para o enfrentamento de adversidades causadas por eventos meteorológicos extremos | N16: Programa Basico de Ciências Ambientais | O16: CA | P16: Ciências Exatas e da Terra | Q16: Climatologia | R16: Instituto Nacional de Pesquisas Espaciais | S16: INPE | T16: SP | U16: SE | V16: Brasil | W16: Instituto Nacional de Pesquisas Espaciais | X16: INPE | Y16: SP | Z16: SE | AA16: Brasil | AB16: DCTI | AC16: COCAM | AD16: 26/06/2026 | AE16: 02:16:18 | AF16: 26/06/2026 | AG16: 02:16:36 | AH16: 7 | AI16: 1048320 | AJ16: 137184 | AK16: 0 | AL16: 1185504 | AM16: Instituto Nacional de Pesquisas Espaciais | AN16: INPE | AO16: SP | AP16: SE | AQ16: Brasil | AR16: 4978912302419377 | AS16: 46202.465 | AT16: PCI2026 | AU16: Chamada CNPq/MCTI/FNDCT Nº 12/2026 - Programa PCI | AV16: Chamada: Chamada CNPq/MCTI/FNDCT Nº 12/2026 - Faixa 3: Projetos de Pesquisa vinculados a | AW16: 12/2026 | AX16: Chamada CNPq/MCTI/FNDCT Nº 12/2026 - Faixa 3: Projetos de Pesquisa vinculados a UPs Grandes (acima de 200 servidores) | AY16: 27/04/2026 | AZ16: 27/06/2026 | BA16: caio.coelho@inpe.br | BB16: 402015/2026-6 | BC16: Caio Augusto dos Santos Coelho | BD16: Instituto Nacional de Pesquisas Espaciais | BE16: INPE | BF16: =IF(AND(BG16,BI16,BL16,BM16),TRUE,FALSE) -> TRUE | BG16: TRUE | BH16: 2005 | BI16: TRUE | BJ16: Faixa 3 | BK16: Faixa 3 (20 propostas) | BL16: TRUE | BM16: TRUE | BN16: TRUE | BO16: - Instituto Nacional de Pesquisas Espaciais - PA: (Servidor público - Pesquisador) - Instituto Nacional de Pesquisas Espaciais: (em branco) | BP16: =IF(IFERROR(VLOOKUP(A16,[1]Planilha1!$A:$A,1,0),FALSE)=FALSE,FALSE,TRUE) -> TRUE
A17: 402012/2026-7 | B17: APQ | D17: 46204 | E17: 47664 | F17: 05019430641 | G17: Caleb Guedes Miranda dos Santos | H17: http://lattes.cnpq.br/1597761083606654 | I17: Caleb Guedes Miranda dos Santos | K17: Caleb Guedes Miranda dos Santos | L17: 5116502 | M17: Perfil imunofenotípico e multiômico de biomarcadores livres e derivados de vesículas extracelulares induzidos pelo exercício para monitoramento fisiológico em atletas de elite e militares | N17: Programa Especial de Biotecnologia e Recursos Genéticos - COBRG | O17: BI | P17: Ciências Biológicas | Q17: Biotecnologia em Saúde Humana e Animal | R17: Instituto de Biologia do Exécito | S17: IBEX | T17: RJ | U17: SE | V17: Brasil | W17: Instituto de Biologia do Exécito | X17: IBEX | Y17: RJ | Z17: SE | AA17: Brasil | AB17: DCTI | AC17: COBEN | AD17: 26/06/2026 | AE17: 00:50:44 | AF17: 26/06/2026 | AG17: 00:50:52 | AH17: 3 | AI17: 761280 | AJ17: 80000 | AK17: 0 | AL17: 841280 | AM17: Instituto de Biologia do Exécito | AN17: IBEX | AO17: RJ | AP17: SE | AQ17: Brasil | AR17: 1597761083606654 | AS17: 46202.465 | AT17: PCI2026 | AU17: Chamada CNPq/MCTI/FNDCT Nº 12/2026 - Programa PCI | AV17: Chamada: Chamada CNPq/MCTI/FNDCT Nº 12/2026 - Faixa 3: Projetos de Pesquisa vinculados a | AW17: 12/2026 | AX17: Chamada CNPq/MCTI/FNDCT Nº 12/2026 - Faixa 3: Projetos de Pesquisa vinculados a UPs Grandes (acima de 200 servidores) | AY17: 27/04/2026 | AZ17: 27/06/2026 | BA17: calebguedes@gmail.com | BB17: 402012/2026-7 | BC17: Caleb Guedes Miranda dos Santos | BD17: Instituto de Biologia do Exécito | BE17: IBEX | BF17: =IF(AND(BG17,BI17,BL17,BM17),TRUE,FALSE) -> FALSE | BG17: FALSE | BH17: 2016 | BI17: FALSE | BJ17: Faixa 3 | BK17: Faixa 3 (1 propostas) | BL17: TRUE | BM17: TRUE | BN17: TRUE | BO17: - Instituto de Biologia do Exécito: (Servidor público - Major Farmaceutico - Pesquisador) | BP17: =IF(IFERROR(VLOOKUP(A17,[1]Planilha1!$A:$A,1,0),FALSE)=FALSE,FALSE,TRUE) -> FALSE
A18: 402095/2026-0 | B18: APQ | D18: 46204 | E18: 47664 | F18: 03585876706 | G18: Camila Cherem Ribas | H18: http://lattes.cnpq.br/4928616387172275 | I18: Camila Cherem Ribas | K18: Camila Cherem Ribas, Andrea Correa Flores Albuquerque, Moysés Mendes de Lima, Roberto Oliveira dos Santos, Inácio de Oliveira Lima Neto, Clausewykson Ribeiro da Cunha | L18: 5116587 | M18: Observatório de Repositórios, Integração, Organização e Navegação de Dados Científicos (ORION) | N18: PROGRAMA BASICO DE CIENCIA DA COMPUTACAO | O18: CC | P18: Ciências Exatas e da Terra | Q18: Banco de Dados | R18: Instituto Nacional de Pesquisas da Amazônia | S18: INPA | T18: AM | U18: NO | V18: Brasil | W18: Instituto Nacional de Pesquisas da Amazônia | X18: INPA | Y18: AM | Z18: NO | AA18: Brasil | AB18: DCTI | AC18: COCEC | AD18: 27/06/2026 | AE18: 06:50:40 | AF18: 27/06/2026 | AG18: 09:52:18 | AH18: 9 | AI18: 1363020 | AJ18: 136796 | AK18: 0 | AL18: 1499816 | AM18: Instituto Nacional de Pesquisas da Amazônia | AN18: INPA | AO18: AM | AP18: NO | AQ18: Brasil | AR18: 4928616387172275 | AS18: 46202.465 | AT18: PCI2026 | AU18: Chamada CNPq/MCTI/FNDCT Nº 12/2026 - Programa PCI | AV18: Chamada: Chamada CNPq/MCTI/FNDCT Nº 12/2026 - Faixa 3: Projetos de Pesquisa vinculados a | AW18: 12/2026 | AX18: Chamada CNPq/MCTI/FNDCT Nº 12/2026 - Faixa 3: Projetos de Pesquisa vinculados a UPs Grandes (acima de 200 servidores) | AY18: 27/04/2026 | AZ18: 27/06/2026 | BA18: camilaribas@gmail.com | BB18: 402095/2026-0 | BC18: Camila Cherem Ribas | BD18: Instituto Nacional de Pesquisas da Amazônia | BE18: INPA | BF18: =IF(AND(BG18,BI18,BL18,BM18),TRUE,FALSE) -> TRUE | BG18: TRUE | BH18: 2005 | BI18: TRUE | BJ18: Faixa 3 | BK18: Faixa 3 (15 propostas) | BL18: TRUE | BM18: TRUE | BN18: TRUE | BO18: - American Museum of Natural History: (Research Associate - Research Associate) - Instituto Nacional de Pesquisas da Amazônia: (Servidor público - Tecnologista H-III) - Karlsruher Institut für Technologie: (Pesquisador visitante - Pesquisador visitante - PDE/CNPq) | BP18: =IF(IFERROR(VLOOKUP(A18,[1]Planilha1!$A:$A,1,0),FALSE)=FALSE,FALSE,TRUE) -> TRUE
A19: 402179/2026-9 | B19: APQ | D19: 46204 | E19: 47664 | F19: 05137625825 | G19: Carlos Roberto Jorge Soares | H19: http://lattes.cnpq.br/3805602544840562 | I19: Carlos Roberto Jorge Soares | K19: Carlos Roberto Jorge Soares, Alvaro Antonio Alencar Queiroz, Cibele Nunes Peroni, Emerson Soares Bernardes, Luís Alberto Pereira Dias, Margareth Mie Nakamura Matsuda, Andrea Glezer, Joao Ezequiel de Oliveira, Daniel Perez | L19: 5116673 | M19: Desenvolvimento e Avaliação Teranóstica de Antagonistas do Receptor de Prolactina em Cânceres Prolactino Dependentes | N19: Programa Especial de Biotecnologia e Recursos Genéticos - COBRG | O19: BI | P19: Ciências Biológicas | Q19: Novas Drogas Terapêuticas | R19: COMISSAO NACIONAL DE ENERGIA NUCLEAR | S19: CNEN | T19: RJ | U19: SE | V19: Brasil | W19: COMISSAO NACIONAL DE ENERGIA NUCLEAR | X19: CNEN | Y19: RJ | Z19: SE | AA19: Brasil | AB19: DCTI | AC19: COBEN | AD19: 26/06/2026 | AE19: 16:30:51 | AF19: 27/06/2026 | AG19: 09:57:29 | AH19: 4 | AI19: 829920 | AJ19: 40000 | AK19: 0 | AL19: 869920 | AM19: COMISSAO NACIONAL DE ENERGIA NUCLEAR | AN19: CNEN | AO19: RJ | AP19: SE | AQ19: Brasil | AR19: 3805602544840562 | AS19: 46202.465 | AT19: PCI2026 | AU19: Chamada CNPq/MCTI/FNDCT Nº 12/2026 - Programa PCI | AV19: Chamada: Chamada CNPq/MCTI/FNDCT Nº 12/2026 - Faixa 3: Projetos de Pesquisa vinculados a | AW19: 12/2026 | AX19: Chamada CNPq/MCTI/FNDCT Nº 12/2026 - Faixa 3: Projetos de Pesquisa vinculados a UPs Grandes (acima de 200 servidores) | AY19: 27/04/2026 | AZ19: 27/06/2026 | BA19: crsoares@ipen.br | BB19: 402179/2026-9 | BC19: Carlos Roberto Jorge Soares | BD19: COMISSAO NACIONAL DE ENERGIA NUCLEAR | BE19: CNEN | BF19: =IF(AND(BG19,BI19,BL19,BM19),TRUE,FALSE) -> TRUE | BG19: TRUE | BH19: 2000 | BI19: TRUE | BJ19: Faixa 3 | BK19: Faixa 3 (32 propostas) | BL19: TRUE | BM19: TRUE | BN19: TRUE | BO19: - COMISSAO NACIONAL DE ENERGIA NUCLEAR: (Servidor público - Pesquisador) - Universidade de São Paulo: (Professor - Responsável por curso de pós-graduação) - Fundação de Amparo à Pesquisa do Estado da Bahia: (Membro de comitê assessor) - Coordenação de Aperfeiçoamento de Pessoal de Nível Superior: (Membro de comitê assessor) - Conselho Nacional de Desenvolvimento Científico e Tecnológico: (Membro de comitê assessor) - Instituto de Pesquisas Energéticas e Nucleares: (em branco) - Universidade Estadual de Campinas: (em branco) | BP19: =IF(IFERROR(VLOOKUP(A19,[1]Planilha1!$A:$A,1,0),FALSE)=FALSE,FALSE,TRUE) -> TRUE
A20: 402215/2026-5 | B20: APQ | D20: 46204 | E20: 47664 | F20: 16756902865 | G20: Cecília Chaves Guedes e Silva | H20: http://lattes.cnpq.br/3598507725109908 | I20: Cecília Chaves Guedes e Silva | K20: Cecília Chaves Guedes e Silva, Dolores Ribeiro Ricci Lazar, Flavio Machado de Souza Carvalho, Thiago dos Santos Ferreira, Anelyse Arata | L20: 5116710 | M20: Novas Estratégias no Desenvolvimento de Cerâmicas para a Odontologia: Integração entre Processamento e Desempenho | N20: PROGRAMA BASICO DE ENGENHARIA DE MATERIAIS E METALURGIA | O20: MM | P20: Engenharias | Q20: Cerâmicos | R20: Instituto de Pesquisas Energéticas e Nucleares | S20: IPEN/CNEN | T20: SP | U20: SE | V20: Brasil | W20: Instituto de Pesquisas Energéticas e Nucleares | X20: IPEN/CNEN | Y20: SP | Z20: SE | AA20: Brasil | AB20: DCTI | AC20: COBEN | AD20: 26/06/2026 | AE20: 11:10:44 | AF20: 27/06/2026 | AG20: 09:59:31 | AH20: 3 | AI20: 648960 | AJ20: 70185 | AK20: 0 | AL20: 719145 | AR20: 3598507725109908 | AS20: 46202.465 | AT20: PCI2026 | AU20: Chamada CNPq/MCTI/FNDCT Nº 12/2026 - Programa PCI | AV20: Chamada: Chamada CNPq/MCTI/FNDCT Nº 12/2026 - Faixa 3: Projetos de Pesquisa vinculados a | AW20: 12/2026 | AX20: Chamada CNPq/MCTI/FNDCT Nº 12/2026 - Faixa 3: Projetos de Pesquisa vinculados a UPs Grandes (acima de 200 servidores) | AY20: 27/04/2026 | AZ20: 27/06/2026 | BA20: ceciliacguedes@gmail.com | BB20: 402215/2026-5 | BC20: Cecília Chaves Guedes e Silva | BD20: Instituto de Pesquisas Energéticas e Nucleares | BE20: IPEN/CNEN | BF20: =IF(AND(BG20,BI20,BL20,BM20),TRUE,FALSE) -> TRUE | BG20: TRUE | BH20: 2005 | BI20: TRUE | BJ20: Faixa 3 | BK20: Faixa 3 (6 propostas) | BL20: TRUE | BM20: TRUE | BN20: TRUE | BO20: - Instituto de Pesquisas Energéticas e Nucleares: (Servidor público - Pesquisadora) - Instituto de Pesquisas Energéticas e Nucleares: (Servidor público - Professor de pós-graduação) - Instituto de Pesquisas Energéticas e Nucleares: (Servidor público - Membro do comitê de Bolsas PIBIC/PROBIT) - Fundação de Amparo à Pesquisa do Estado de São Paulo: (Membro de comitê assessor) - Associação Brasileira de Cerâmica: (COLABORADOR - Membro do Conselho Diretor) | BP20: =IF(IFERROR(VLOOKUP(A20,[1]Planilha1!$A:$A,1,0),FALSE)=FALSE,FALSE,TRUE) -> TRUE
A21: 402276/2026-4 | B21: APQ | D21: 46204 | E21: 47664 | F21: 53431685234 | G21: Charles Eugene Zartman | H21: http://lattes.cnpq.br/1704819172861021 | I21: Charles Eugene Zartman | K21: Charles Eugene Zartman, Vania Nobuko Yoshikawa, Dirce Leimi Komura, Maria de Lourdes da Costa Soares Morais, Alberto Vicentini, Mike Hopkins, Matheus Lopes Silva, Ires Paula de Andrade Miranda, Flavia Machado Durgante, | L21: 5116774 | M21: BIOCOLABS: Biodiversidade da Flora e Funga Conservada através de Laboratórios da botânica e Aquisição de Bioextratos Amazônicos | N21: PROGRAMA BASICO DE BOTANICA | O21: BO | P21: Ciências Biológicas | Q21: Taxonomia Vegetal | R21: Instituto Nacional de Pesquisas da Amazônia | S21: INPA | T21: AM | U21: NO | V21: Brasil | W21: Instituto Nacional de Pesquisas da Amazônia | X21: INPA | Y21: AM | Z21: NO | AA21: Brasil | AB21: DCTI | AC21: COEBI | AD21: 26/06/2026 | AE21: 11:21:19 | AF21: 27/06/2026 | AG21: 10:03:22 | AH21: 10 | AI21: 1115520 | AJ21: 49500 | AK21: 0 | AL21: 1165020 | AM21: Instituto Nacional de Pesquisas da Amazônia | AN21: INPA | AO21: AM | AP21: NO | AQ21: Brasil | AR21: 1704819172861021 | AS21: 46202.465 | AT21: PCI2026 | AU21: Chamada CNPq/MCTI/FNDCT Nº 12/2026 - Programa PCI | AV21: Chamada: Chamada CNPq/MCTI/FNDCT Nº 12/2026 - Faixa 3: Projetos de Pesquisa vinculados a | AW21: 12/2026 | AX21: Chamada CNPq/MCTI/FNDCT Nº 12/2026 - Faixa 3: Projetos de Pesquisa vinculados a UPs Grandes (acima de 200 servidores) | AY21: 27/04/2026 | AZ21: 27/06/2026 | BA21: chaszartman@gmail.com | BB21: 402276/2026-4 | BC21: Charles Eugene Zartman | BD21: Instituto Nacional de Pesquisas da Amazônia | BE21: INPA | BF21: =IF(AND(BG21,BI21,BL21,BM21),TRUE,FALSE) -> TRUE | BG21: TRUE | BH21: 2004 | BI21: TRUE | BJ21: Faixa 3 | BK21: Faixa 3 (15 propostas) | BL21: TRUE | BM21: TRUE | BN21: TRUE | BO21: - Instituto Nacional de Pesquisas da Amazônia: (Orientador - Nucleo permanente PPG-BOT INPA) - Instituto Nacional de Pesquisas da Amazônia: (Servidor público - Pesquisador Titular III) | BP21: =IF(IFERROR(VLOOKUP(A21,[1]Planilha1!$A:$A,1,0),FALSE)=FALSE,FALSE,TRUE) -> TRUE
A22: 402243/2026-9 | B22: APQ | D22: 46204 | E22: 47664 | F22: 09471587824 | G22: Cláudia Vilega Rodrigues | H22: http://lattes.cnpq.br/9527193250756102 | I22: Cláudia Vilega Rodrigues | K22: Cláudia Vilega Rodrigues, Carlos Alexandre Wuensche de Souza, Odylio Denys de Aguiar, Ana Carolina Mattiuci Figueiredo, Marina Machado Cunha e Mello, Fernando Falkenberg Marques, Gustavo Henrique da Silva Santos, | L22: 5116741 | M22: Da Instrumentação de Fronteira à Análise de Dados Astrofísicos: Integração e Resultados | N22: PROGRAMA BASICO DE ASTRONOMIA | O22: FA | P22: Ciências Exatas e da Terra | Q22: Processamento de Dados Astronômicos | R22: Instituto Nacional de Pesquisas Espaciais | S22: INPE | T22: SP | U22: SE | V22: Brasil | W22: Instituto Nacional de Pesquisas Espaciais | X22: INPE | Y22: SP | Z22: SE | AA22: Brasil | AB22: DCTI | AC22: COCEC | AD22: 26/06/2026 | AE22: 17:43:05 | AF22: 27/06/2026 | AG22: 10:01:28 | AH22: 7 | AI22: 1460400 | AJ22: 39840 | AK22: 0 | AL22: 1500240 | AM22: Instituto Nacional de Pesquisas Espaciais | AN22: INPE | AO22: SP | AP22: SE | AQ22: Brasil | AR22: 9527193250756102 | AS22: 46202.465 | AT22: PCI2026 | AU22: Chamada CNPq/MCTI/FNDCT Nº 12/2026 - Programa PCI | AV22: Chamada: Chamada CNPq/MCTI/FNDCT Nº 12/2026 - Faixa 3: Projetos de Pesquisa vinculados a | AW22: 12/2026 | AX22: Chamada CNPq/MCTI/FNDCT Nº 12/2026 - Faixa 3: Projetos de Pesquisa vinculados a UPs Grandes (acima de 200 servidores) | AY22: 27/04/2026 | AZ22: 27/06/2026 | BA22: claudia.rodrigues@inpe.br | BB22: 402243/2026-9 | BC22: Cláudia Vilega Rodrigues | BD22: Instituto Nacional de Pesquisas Espaciais | BE22: INPE | BF22: =IF(AND(BG22,BI22,BL22,BM22),TRUE,FALSE) -> TRUE | BG22: TRUE | BH22: 1997 | BI22: TRUE | BJ22: Faixa 3 | BK22: Faixa 3 (20 propostas) | BL22: TRUE | BM22: TRUE | BN22: TRUE | BO22: - Instituto Nacional de Pesquisas Espaciais: (Pesquisador titular) - Laboratório Nacional de Astrofísica: (COLABORADOR - não há) - Conselho Nacional de Desenvolvimento Científico e Tecnológico: (Assessor - Nao se aplica) - International Astronomical Union: (Membro da Comissão B6 - Membro da Comissão B6) - SOuthern Astrophysical Research Telescope: (Membro do Conselho Diretor - Membro do Conselho Diretor) | BP22: =IF(IFERROR(VLOOKUP(A22,[1]Planilha1!$A:$A,1,0),FALSE)=FALSE,FALSE,TRUE) -> TRUE
A23: 402298/2026-8 | B23: APQ | D23: 46204 | E23: 47664 | F23: 27021726600 | G23: Clédola Cássia Oliveira de Tello | H23: http://lattes.cnpq.br/7628216289944686 | I23: Clédola Cássia Oliveira de Tello | K23: Clédola Cássia Oliveira de Tello, Rogerio Pimenta Mourao, Heloisa Maria Santos Oliveira, Jamile Salim Fuina, Daisy Mary Marchezini dos Santos, Maria Judite Afonso Haucz, Thais Braga Teixeira, Isabella Lobo Filgueiras de Miranda | L23: 5116796 | M23: Capacitação técnico-científica para o projeto do CENTENA - Centro Tecnológico Nuclear e Ambiental | N23: PROGRAMA BASICO DE ENGENHARIA NUCLEAR | O23: EN | P23: Engenharias | Q23: Rejeitos de Combustível Nuclear | R23: COMISSAO NACIONAL DE ENERGIA NUCLEAR | S23: CNEN | T23: RJ | U23: SE | V23: Brasil | W23: COMISSAO NACIONAL DE ENERGIA NUCLEAR | X23: CNEN | Y23: RJ | Z23: SE | AA23: Brasil | AB23: DCTI | AC23: COBEN | AD23: 26/06/2026 | AE23: 18:40:07 | AF23: 27/06/2026 | AG23: 10:04:47 | AH23: 10 | AI23: 1395680 | AJ23: 104320 | AK23: 0 | AL23: 1500000 | AM23: COMISSAO NACIONAL DE ENERGIA NUCLEAR | AN23: CNEN | AO23: RJ | AP23: SE | AQ23: Brasil | AR23: 7628216289944686 | AS23: 46202.465 | AT23: PCI2026 | AU23: Chamada CNPq/MCTI/FNDCT Nº 12/2026 - Programa PCI | AV23: Chamada: Chamada CNPq/MCTI/FNDCT Nº 12/2026 - Faixa 3: Projetos de Pesquisa vinculados a | AW23: 12/2026 | AX23: Chamada CNPq/MCTI/FNDCT Nº 12/2026 - Faixa 3: Projetos de Pesquisa vinculados a UPs Grandes (acima de 200 servidores) | AY23: 27/04/2026 | AZ23: 27/06/2026 | BA23: tellocc@cdtn.br | BB23: 402298/2026-8 | BC23: Clédola Cássia Oliveira de Tello | BD23: COMISSAO NACIONAL DE ENERGIA NUCLEAR | BE23: CNEN | BF23: =IF(AND(BG23,BI23,BL23,BM23),TRUE,FALSE) -> TRUE | BG23: TRUE | BH23: 2001 | BI23: TRUE | BJ23: Faixa 3 | BK23: Faixa 3 (32 propostas) | BL23: TRUE | BM23: TRUE | BN23: TRUE | BO23: - COMISSAO NACIONAL DE ENERGIA NUCLEAR: (Servidor público - Tecnologista Senior) - Associação Brasileira para Desenvolvimento de Atividades Nucleares.: (Membro de comitê assessor) - Centro de Desenvolvimento da Tecnologia Nuclear: (em branco) | BP23: =IF(IFERROR(VLOOKUP(A23,[1]Planilha1!$A:$A,1,0),FALSE)=FALSE,FALSE,TRUE) -> TRUE
A24: 402357/2026-4 | B24: APQ | D24: 46204 | E24: 47664 | F24: 72952229287 | G24: Cleo Quaresma Dias Júnior | H24: http://lattes.cnpq.br/9857237626091379 | I24: Cleo Quaresma Dias Júnior | K24: Cleo Quaresma Dias Júnior, Luiz Antonio Candido, Aline Corrêa de Sousa, Alderlene Pimentel de Brito, Keila Rêgo Mendes, Israel de Jesus Sampaio Filho, Flávia Regina Capellotto Costa, Bruce Rider Forsberg, Carlos Alberto Nobre | L24: 5116855 | M24: Amazônia Central como Hotspot Emergente de Mudanças: Plataforma Integrada de Monitoramento e Modelagem para Estudos de Impactos Hidroclimático e Ambiental | N24: Programa Basico de Ciências Ambientais | O24: CA | P24: Outra | Q24: Ciências Ambientais | R24: Instituto Nacional de Pesquisas da Amazônia | S24: INPA | T24: AM | U24: NO | V24: Brasil | W24: Instituto Nacional de Pesquisas da Amazônia | X24: INPA | Y24: AM | Z24: NO | AA24: Brasil | AB24: DCTI | AC24: COCAM | AD24: 27/06/2026 | AE24: 15:57:17 | AF24: 27/06/2026 | AG24: 15:57:32 | AH24: 9 | AI24: 1347060 | AJ24: 148940 | AK24: 0 | AL24: 1496000 | AM24: Instituto Nacional de Pesquisas da Amazônia | AN24: INPA | AO24: AM | AP24: NO | AQ24: Brasil | AR24: 9857237626091379 | AS24: 46202.465 | AT24: PCI2026 | AU24: Chamada CNPq/MCTI/FNDCT Nº 12/2026 - Programa PCI | AV24: Chamada: Chamada CNPq/MCTI/FNDCT Nº 12/2026 - Faixa 3: Projetos de Pesquisa vinculados a | AW24: 12/2026 | AX24: Chamada CNPq/MCTI/FNDCT Nº 12/2026 - Faixa 3: Projetos de Pesquisa vinculados a UPs Grandes (acima de 200 servidores) | AY24: 27/04/2026 | AZ24: 27/06/2026 | BA24: cleo.quaresma@ifpa.edu.br | BB24: 402357/2026-4 | BC24: Cleo Quaresma Dias Júnior | BD24: Instituto Nacional de Pesquisas da Amazônia | BE24: INPA | BF24: =IF(AND(BG24,BI24,BL24,BM24),TRUE,FALSE) -> TRUE | BG24: TRUE | BH24: 2015 | BI24: TRUE | BJ24: Faixa 3 | BK24: Faixa 3 (15 propostas) | BL24: TRUE | BM24: TRUE | BN24: TRUE | BO24: - Instituto Nacional de Pesquisas da Amazônia: (COLABORADOR - Colaborador PPG em Clima e Ambiente) - Instituto Nacional de Pesquisas da Amazônia: (COLABORADOR - Coordenador da Micrometeorologia do ATTO) - Instituto Nacional de Pesquisas da Amazônia: (Servidor público - Pesquisador) - Universidade Federal do Pará: (COLABORADOR - Colaborador PPG em Ciências Ambientais) - Max-Planck-Institut für Biogeochemie - Jena: (COLABORADOR - Colaborador) - Universität Leipzig: (COLABORADOR - Colaborador) - Universidade Federal de Santa Maria: (COLABORADOR - Colaborador) - Universíade de Taubaté: (COLABORADOR - Colaborador) - Universidade de São Paulo: (em branco) | BP24: =IF(IFERROR(VLOOKUP(A24,[1]Planilha1!$A:$A,1,0),FALSE)=FALSE,FALSE,TRUE) -> TRUE
A25: 401137/2026-0 | B25: APQ | D25: 46204 | E25: 47664 | F25: 13881249800 | G25: Cléria Mendonça de Moraes | H25: http://lattes.cnpq.br/4518337589148307 | I25: Cléria Mendonça de Moraes | K25: Cléria Mendonça de Moraes, Newton Ricardo Pereira Souza, Cecil Albert Boston, Julio Cesar Fraulob Aquino, Beatriz Helena Baldez Vasconcelos, Luciana da Silva Barros, Jackeline da Costa Maciel Silva, Augusto Vicente Ferreira | L25: 5115153 | M25: Horto Didático integrado ao Ensino, à Pesquisa e à Inovação de bioprodutos a partir de Plantas Medicinais da Amazônia Setentrional | N25: PROGRAMA BASICO DE SAUDE COLETIVA | O25: SN | P25: Ciências da Saúde | Q25: Epidemiologia | R25: Universidade Federal de Roraima | S25: UFRR | T25: RR | U25: NO | V25: Brasil | W25: Universidade Federal de Roraima | X25: UFRR | Y25: RR | Z25: NO | AA25: Brasil | AB25: DCTI | AC25: COSAU | AD25: 27/05/2026 | AE25: 23:50:44 | AF25: 27/05/2026 | AG25: 23:50:51 | AH25: 12 | AI25: 1440000 | AJ25: 150000 | AK25: 0 | AL25: 1590000 | AM25: Universidade Federal de Roraima | AN25: UFRR | AO25: RR | AP25: NO | AQ25: Brasil | AR25: 4518337589148307 | AS25: 46202.465 | AT25: PCI2026 | AU25: Chamada CNPq/MCTI/FNDCT Nº 12/2026 - Programa PCI | AV25: Chamada: Chamada CNPq/MCTI/FNDCT Nº 12/2026 - Faixa 3: Projetos de Pesquisa vinculados a | AW25: 12/2026 | AX25: Chamada CNPq/MCTI/FNDCT Nº 12/2026 - Faixa 3: Projetos de Pesquisa vinculados a UPs Grandes (acima de 200 servidores) | AY25: 27/04/2026 | AZ25: 27/06/2026 | BA25: clemmsp@gmail.com | BB25: 401137/2026-0 | BC25: Cléria Mendonça de Moraes | BD25: Universidade Federal de Roraima | BE25: UFRR | BF25: =IF(AND(BG25,BI25,BL25,BM25),TRUE,FALSE) -> FALSE | BG25: FALSE | BH25: 2000 | BI25: FALSE | BJ25: Faixa 3 | BK25: Faixa 3 (1 propostas) | BL25: TRUE | BM25: TRUE | BN25: TRUE | BO25: - Universidade Federal de Roraima: (Servidor público - Professor do Magistério Superior) - Fundação Oswaldo Cruz: (em branco) | BP25: =IF(IFERROR(VLOOKUP(A25,[1]Planilha1!$A:$A,1,0),FALSE)=FALSE,FALSE,TRUE) -> FALSE
A26: 401983/2026-9 | B26: APQ | D26: 46204 | E26: 47664 | F26: 59264594000 | G26: Cristiano Max Wrasse | H26: http://lattes.cnpq.br/2348934439826171 | I26: Cristiano Max Wrasse | K26: Cristiano Max Wrasse, Clezio Marcos De Nardin, Delano Gobbi, Diego Barros Silva, Emilia Correia, Fábio Becker Guedes, Jean Carlo Santos, Joaquim Eduardo Rezende Costa, Láysa Cristina Araujo Resende Chagas, Lígia Alves da | L26: 5116464 | M26: Desenvolvimento e implementação de produtos de clima espacial para proteção às infraestruturas críticas | N26: Programa Basico de Geociência | O26: GC | P26: Ciências Exatas e da Terra | Q26: Geofísica | R26: Instituto Nacional de Pesquisas Espaciais | S26: INPE | T26: SP | U26: SE | V26: Brasil | W26: Instituto Nacional de Pesquisas Espaciais | X26: INPE | Y26: SP | Z26: SE | AA26: Brasil | AB26: DCTI | AC26: COCQG | AD26: 25/06/2026 | AE26: 16:13:45 | AF26: 25/06/2026 | AG26: 16:17:50 | AH26: 3 | AI26: 648960 | AJ26: 0 | AK26: 0 | AL26: 648960 | AM26: Instituto Nacional de Pesquisas Espaciais | AN26: INPE | AO26: SP | AP26: SE | AQ26: Brasil | AR26: 2348934439826171 | AS26: 46202.465 | AT26: PCI2026 | AU26: Chamada CNPq/MCTI/FNDCT Nº 12/2026 - Programa PCI | AV26: Chamada: Chamada CNPq/MCTI/FNDCT Nº 12/2026 - Faixa 3: Projetos de Pesquisa vinculados a | AW26: 12/2026 | AX26: Chamada CNPq/MCTI/FNDCT Nº 12/2026 - Faixa 3: Projetos de Pesquisa vinculados a UPs Grandes (acima de 200 servidores) | AY26: 27/04/2026 | AZ26: 27/06/2026 | BA26: cristiano.wrasse@gmail.com | BB26: 401983/2026-9 | BC26: Cristiano Max Wrasse | BD26: Instituto Nacional de Pesquisas Espaciais | BE26: INPE | BF26: =IF(AND(BG26,BI26,BL26,BM26),TRUE,FALSE) -> TRUE | BG26: TRUE | BH26: 2004 | BI26: TRUE | BJ26: Faixa 3 | BK26: Faixa 3 (20 propostas) | BL26: TRUE | BM26: TRUE | BN26: TRUE | BO26: - Instituto Nacional de Pesquisas Espaciais: (Servidor público - Pesquisador) | BP26: =IF(IFERROR(VLOOKUP(A26,[1]Planilha1!$A:$A,1,0),FALSE)=FALSE,FALSE,TRUE) -> TRUE
A27: 402263/2026-0 | B27: APQ | D27: 46204 | E27: 47664 | F27: 48882291200 | G27: Cristine Bastos do Amarante | H27: http://lattes.cnpq.br/4101983776191966 | I27: Cristine Bastos do Amarante | K27: Cristine Bastos do Amarante, Amilcar Carvalho Mendes, Tarcízio Macedo, José Francisco Berrêdo Reis da Silva, Marcos Paulo Alves de Sousa, Sâmia Batista e Silva, Gerson Valente da Costa, Jose Paulo Sarmento, Lourdes de | L27: 5116761 | M27: Fortalecimento do Ecossistema de Inovação do MPEG: estratégias para aumento de TRL e valoração de tecnologias para a bioeconomia e o desenvolvimento regional  INOVAGOELDI | N27: PROGRAMA BASICO DE ADMINISTRACAO | O27: AE | P27: Ciências Sociais Aplicadas | Q27: Planejamento em Ciência e Tecnologia | R27: Museu Paraense Emílio Goeldi | S27: MPEG | T27: PA | U27: NO | V27: Brasil | W27: Museu Paraense Emílio Goeldi | X27: MPEG | Y27: PA | Z27: NO | AA27: Brasil | AB27: DCTI | AC27: COSAE | AD27: 26/06/2026 | AE27: 12:44:09 | AF27: 27/06/2026 | AG27: 10:02:34 | AH27: 6 | AI27: 1023360 | AJ27: 130000 | AK27: 0 | AL27: 1153360 | AR27: 4101983776191966 | AS27: 46202.465 | AT27: PCI2026 | AU27: Chamada CNPq/MCTI/FNDCT Nº 12/2026 - Programa PCI | AV27: Chamada: Chamada CNPq/MCTI/FNDCT Nº 12/2026 - Faixa 3: Projetos de Pesquisa vinculados a | AW27: 12/2026 | AX27: Chamada CNPq/MCTI/FNDCT Nº 12/2026 - Faixa 3: Projetos de Pesquisa vinculados a UPs Grandes (acima de 200 servidores) | AY27: 27/04/2026 | AZ27: 27/06/2026 | BA27: cristineamarante@yahoo.com.br | BB27: 402263/2026-0 | BC27: Cristine Bastos do Amarante | BD27: Museu Paraense Emílio Goeldi | BE27: MPEG | BF27: =IF(AND(BG27,BI27,BL27,BM27),TRUE,FALSE) -> TRUE | BG27: TRUE | BH27: 2010 | BI27: TRUE | BJ27: Faixa 3 | BK27: Faixa 3 (24 propostas) | BL27: TRUE | BM27: TRUE | BN27: FALSE | BO27: - Museu Paraense Emílio Goeldi: (TECNOLOGISTA SÊNIOR) | BP27: =IF(IFERROR(VLOOKUP(A27,[1]Planilha1!$A:$A,1,0),FALSE)=FALSE,FALSE,TRUE) -> TRUE
